#VRML_SIM R2021a utf8
WorldInfo {
  basicTimeStep 16
  coordinateSystem "NUE"
  contactProperties [
    ContactProperties {
      material2 "slippy"
      coulombFriction [
        0
      ]
    }
    ContactProperties {
      material2 "block"
      coulombFriction [
        0.01
      ]
    }
    ContactProperties {
      material2 "ball_bearing"
      coulombFriction [
        0
      ]
    }
  ]
}
Viewpoint {
  orientation 0.15383377625143313 -0.8597631354425371 -0.4869728126068658 3.8051166991606724
  position 0.46393596151546435 0.831849831249517 -0.6611636557724326
}
Background {
  skyColor [
    0.15 0.45 1
  ]
}
Floor {
  size 2.4 2.4
  appearance Asphalt {
  }
}
target {
  translation -0.639 0.02497547451951153 0.42
  rotation -0.0757765602233323 0.6481120312050156 -0.7577656022333216 -5.626088597840589e-17
  name "target(9)"
}
target {
  translation 0.977 0.024975474519511525 0.6057
  rotation -0.03896321197617513 0.9898912831673099 -0.13637124191660205 2.1883495730114342e-16
  name "target(8)"
}
target {
  translation 0.6867 0.024975474519511525 0.5714
  rotation -0.03896321197617513 0.9898912831673099 -0.13637124191660205 2.1883495730114342e-16
  name "target(7)"
}
target {
  translation 1.0798 0.02497547451951153 -0.2533
  rotation 0.8059109309098598 0.24868508169517867 -0.537273953939948 6.347981521601662e-17
  name "target(6)"
}
target {
  translation 0.366 0.024975474519511525 0.3654
  rotation 0.5132896048118902 0.06843372636024753 -0.8554826746863458 2.491725747762101e-17
  colour 0 1 0
  name "target(5)"
}
target {
  translation -1.0911 0.02497547451951153 -0.7727
  rotation -0.543436796603501 0.8394500867218522 4.124367488403013e-15 -2.3534970991322053e-17
  colour 0 1 0
  name "target(1)"
}
target {
  translation 0.8205 0.024975474519511525 0.4842
  rotation 0.5276696975222741 0.3083589524073046 0.7915045462832297 1.6158807051378174e-17
  colour 0 1 0
  name "target(2)"
}
target {
  translation 1.0199 0.02497547451951153 -1.1002
  rotation -0.47936571947404333 0.8442515227948549 0.23968285973698936 3.55741450952181e-17
  colour 0 1 0
  name "target(3)"
}
DEF Floor_colour Solid {
  translation 0 0.0001 0.4
  children [
    Shape {
      appearance PBRAppearance {
        baseColor 1 0 0
      }
      geometry Plane {
        size 0.4 0.4
      }
    }
  ]
  name "solid(6)"
}
DEF Floor_colour Solid {
  translation 0 0.0001 -0.4
  children [
    Shape {
      appearance PBRAppearance {
        baseColor 0 1 0
      }
      geometry Plane {
        size 0.4 0.4
      }
    }
  ]
  name "solid(5)"
}
DEF WALL_1 Solid {
  translation 1.2 0.05 0
  children [
    DEF WALL_SHAPE Shape {
      appearance PBRAppearance {
        baseColor 0 0.333333 0
        roughness 1
        metalness 0
      }
      geometry Box {
        size 0.02 0.1 2.38
      }
    }
  ]
  boundingObject USE WALL_SHAPE
}
DEF WALL_2 Solid {
  translation -1.2 0.05 0
  children [
    USE WALL_SHAPE
  ]
  name "solid(1)"
  boundingObject USE WALL_SHAPE
}
DEF WALL_3 Solid {
  translation 0 0.05 -1.2
  rotation 0 1 0 1.5708
  children [
    USE WALL_SHAPE
  ]
  name "solid(2)"
  boundingObject USE WALL_SHAPE
}
DEF WALL_4 Solid {
  translation 0 0.05 1.2
  rotation 0 1 0 1.5708
  children [
    USE WALL_SHAPE
  ]
  name "solid(3)"
  boundingObject USE WALL_SHAPE
}
TexturedBackgroundLight {
  texture "empty_office"
}
Robot {
  translation 0.019959152523862194 0.02981830482757359 5.1582841893251484e-08
  rotation 0.0012617578396568994 1.3537918758716176e-06 0.9999992039823438 0.0013624617687495327
  children [
    Compass {
    }
    GPS {
    }
    Receiver {
      channel 1
    }
    Emitter {
    }
    DEF BODY Shape {
      appearance PBRAppearance {
        baseColor 0 0 1
      }
      geometry Box {
        size 0.1 0.03 0.05
      }
    }
    DEF LEFT_WHEEL HingeJoint {
      jointParameters HingeJointParameters {
        position 4.074892064168798e-12
        axis 0 0 -1
        anchor 0.02 -0.005 0.03
      }
      device [
        RotationalMotor {
          name "left_wheel"
        }
      ]
      endPoint Solid {
        translation 0.020000003910463925 -0.004997452491810772 0.029999999997836726
        rotation -1 1.5715526198223608e-09 -1.5715474421749767e-09 1.5708000008261545
        children [
          DEF WHEEL Shape {
            appearance PBRAppearance {
              baseColor 1 0 0
            }
            geometry Cylinder {
              height 0.01
              radius 0.025
            }
          }
        ]
        name "left_wheel"
        boundingObject USE WHEEL
        physics Physics {
        }
      }
    }
    DEF RIGHT_WHEEL HingeJoint {
      jointParameters HingeJointParameters {
        position 4.07847065672431e-12
        axis 0 0 -1
        anchor 0.02 -0.005 -0.03
      }
      device [
        RotationalMotor {
          name "right_wheel"
        }
      ]
      endPoint Solid {
        translation 0.020000003925813963 -0.004997598386196222 -0.030000000006616442
        rotation -1 3.0629729844762447e-11 -2.6551582815474314e-11 1.570799998166978
        children [
          USE WHEEL
        ]
        name "right_wheel"
        boundingObject USE WHEEL
        physics Physics {
        }
      }
    }
    DEF BEARING Solid {
      translation -0.04 -0.02 0
      children [
        Shape {
          appearance PBRAppearance {
            baseColor 0.5 0.5 0.5
          }
          geometry DEF Ball_bearing Sphere {
            radius 0.01
          }
        }
      ]
      name "solid(1)"
      contactMaterial "ball_bearing"
      boundingObject USE Ball_bearing
      physics Physics {
      }
    }
    DEF RIGHT_CLAW HingeJoint {
      jointParameters HingeJointParameters {
        position -1.7767973758964217e-09
        anchor 0.045 0 0.02
      }
      device [
        RotationalMotor {
          name "right_claw"
        }
      ]
      endPoint Solid {
        translation 0.08999999994309457 -3.9319495846734664e-08 0.02000000000009621
        rotation 1 0 0 0
        children [
          DEF CLAW Shape {
            appearance PBRAppearance {
              baseColor 0 0 0
            }
            geometry Box {
              size 0.1 0.01 0.005
            }
          }
        ]
        name "right_claw"
        boundingObject USE CLAW
        physics Physics {
        }
      }
    }
    DEF LEFT_CLAW HingeJoint {
      jointParameters HingeJointParameters {
        position -1.7767982640748414e-09
        anchor 0.045 0 -0.02
      }
      device [
        RotationalMotor {
          name "left_claw"
        }
      ]
      endPoint Solid {
        translation 0.0899999999430946 -3.931949595775697e-08 -0.019999999999903782
        rotation 1 0 0 0
        children [
          DEF CLAW Shape {
            appearance PBRAppearance {
              baseColor 0 0 0
            }
            geometry Box {
              size 0.1 0.01 0.005
            }
          }
        ]
        name "left_claw"
        boundingObject USE CLAW
        physics Physics {
        }
      }
    }
    DistanceSensor {
      translation 0.06 -0.005 0.01
      rotation 1 0 0 -1.5707953071795862
      children [
        Group {
          children [
            DEF ultrasonicShape Transform {
              translation 0 0.01 0
              children [
                Shape {
                  appearance PBRAppearance {
                  }
                  geometry Box {
                    size 0.015 0.045 0.02
                  }
                }
              ]
            }
          ]
        }
      ]
      name "ultrasonic"
      boundingObject USE ultrasonicShape
      lookupTable [
        0 0 0
        0.02 0 0
        0.02 0.02 0
        1.5 1.5 0
      ]
      type "sonar"
      aperture 0.5236
      resolution 0.003
    }
    SharpGP2Y0A02YK0F {
      translation 0.06 0.01 0.01
    }
    TEPT4400 {
      translation 0 0.03 0
    }
  ]
  physics Physics {
  }
  controller "Robot_controller"
}
