#VRML_SIM R2021a utf8
WorldInfo {
  basicTimeStep 16
  coordinateSystem "NUE"
  contactProperties [
    ContactProperties {
      material2 "slippy"
      coulombFriction [
        0
      ]
    }
    ContactProperties {
      material2 "block"
      coulombFriction [
        0.01
      ]
    }
    ContactProperties {
      material2 "ball_bearing"
      coulombFriction [
        0
      ]
    }
  ]
}
Viewpoint {
  orientation 0.5027572378804789 0.7171167080166405 0.4826787615403934 4.409720958629694
  position -2.776818413315181 7.0091153552546865 0.470464425127003
}
Background {
  skyColor [
    0.15 0.45 1
  ]
}
Floor {
  size 2.4 2.4
  appearance Asphalt {
  }
}
Robot {
  translation 0 0.068 -0.4
  rotation 0 1 0 -1.5707953071795862
  children [
    Compass {
      name "compass1"
    }
    Compass {
      rotation 0 1 0 -1.5708
    }
    GPS {
    }
    Receiver {
      channel 1
    }
    Emitter {
      channel 1
    }
    DEF BODY Solid {
      rotation 0 1 0 4.692820414042842e-06
      children [
        Shape {
          appearance PBRAppearance {
            baseColor 0 1 0
          }
          geometry DEF SOLIDBOX Box {
            size 0.2 0.1 0.2
          }
        }
      ]
      name "solid(2)"
      boundingObject USE SOLIDBOX
      physics Physics {
      }
    }
    DEF LEFT_WHEEL HingeJoint {
      jointParameters HingeJointParameters {
        position 4.074892064168798e-12
        axis 0 0 -1
        anchor 0.04 -0.0172 0.11
      }
      device [
        RotationalMotor {
          name "left_wheel"
          maxVelocity 6.702
          maxTorque 0.4
        }
      ]
      endPoint Solid {
        translation 0.04 -0.0172 0.11
        rotation 1 -1.0685734444531301e-09 -1.0685694434178538e-09 1.5707999999999938
        children [
          DEF WHEEL Shape {
            appearance PBRAppearance {
              baseColor 1 0 0
            }
            geometry Cylinder {
              height 0.02
              radius 0.0508
            }
          }
        ]
        name "left_wheel"
        boundingObject USE WHEEL
        physics Physics {
        }
      }
    }
    DEF RIGHT_WHEEL HingeJoint {
      jointParameters HingeJointParameters {
        position 4.07847065672431e-12
        axis 0 0 -1
        anchor 0.04 -0.0172 -0.11
      }
      device [
        RotationalMotor {
          name "right_wheel"
          maxVelocity 6.702
          maxTorque 0.4
        }
      ]
      endPoint Solid {
        translation 0.04 -0.0172 -0.11
        rotation -0.9999999999999999 2.697915798030955e-09 -2.6979185041780757e-09 1.5707953071795426
        children [
          USE WHEEL
        ]
        name "right_wheel"
        boundingObject USE WHEEL
        physics Physics {
        }
      }
    }
    DEF BEARING Solid {
      translation -0.06 -0.059 0
      children [
        Shape {
          appearance PBRAppearance {
            baseColor 0.5 0.5 0.5
          }
          geometry DEF Ball_bearing Sphere {
            radius 0.009
          }
        }
      ]
      name "solid(1)"
      contactMaterial "ball_bearing"
      boundingObject USE Ball_bearing
      physics Physics {
      }
    }
    DEF RIGHT_CLAW HingeJoint {
      jointParameters HingeJointParameters {
        axis 0 1 0
        anchor 0.09 0 0.03
      }
      device [
        RotationalMotor {
          name "right_claw"
        }
        PositionSensor {
          name "right_claw_sensor"
        }
      ]
      endPoint SINGLE_CLAW {
        translation 0.115 -0.035 0.03
      }
    }
    DEF LEFT_CLAW HingeJoint {
      jointParameters HingeJointParameters {
        axis 0 1 0
        anchor 0.09 0 -0.03
      }
      device [
        RotationalMotor {
          name "left_claw"
        }
        PositionSensor {
          name "left_claw_sensor"
        }
      ]
      endPoint SINGLE_CLAW {
        translation 0.115 -0.035 -0.03
      }
    }
    DEF BOX_CLAW HingeJoint {
      jointParameters HingeJointParameters {
        axis 0 0 1
        anchor 0.09 -0.03 0
      }
      device [
        RotationalMotor {
          name "box_claw"
        }
        PositionSensor {
          name "box_claw_sensor"
        }
      ]
    }
    DistanceSensor {
      translation 0.09 -0.055 0.01
      rotation 1 0 0 -1.5707953071795862
      children [
        Group {
          children [
            DEF ultrasonicShape Transform {
              translation 0 0.01 0
              children [
                Shape {
                  appearance PBRAppearance {
                  }
                  geometry Box {
                    size 0.015 0.045 0.02
                  }
                }
              ]
            }
          ]
        }
      ]
      name "ultrasonic"
      boundingObject USE ultrasonicShape
      lookupTable [
        0 0 0
        0.02 0 0.002
        0.02 0.02 0.002
        1.5 1.5 0.002
      ]
      type "sonar"
      aperture 0.5236
      resolution 0.003
    }
    IRSensor {
      translation 0.11 -0.03 0
    }
    TEPT4400 {
      translation 0.155 0.03 0.005
      rotation 0 0 -1 1.0472
      name "TEPT4400_RED"
      red_filter TRUE
    }
    TEPT4400 {
      translation 0.155 0.03 -0.005
      rotation 0 0 -1 1.0472
      name "TEPT4400_GREEN"
      green_filter TRUE
    }
  ]
  name "robot_green"
  physics Physics {
  }
  controller "Robot_controller"
}
Robot {
  translation 0 0.068 0.4
  rotation 0 1 0 1.5708
  children [
    Compass {
      name "compass1"
    }
    Compass {
      rotation 0 1 0 -1.5708
    }
    GPS {
    }
    Receiver {
      channel 1
    }
    Emitter {
      channel 1
    }
    DEF BODY Solid {
      rotation 0 1 0 4.692820414042842e-06
      children [
        Shape {
          appearance PBRAppearance {
            baseColor 1 0 0
          }
          geometry DEF SOLIDBOX Box {
            size 0.2 0.1 0.2
          }
        }
      ]
      name "solid(2)"
      boundingObject USE SOLIDBOX
      physics Physics {
      }
    }
    DEF LEFT_WHEEL HingeJoint {
      jointParameters HingeJointParameters {
        position 4.074892064168798e-12
        axis 0 0 -1
        anchor 0.04 -0.0172 0.11
      }
      device [
        RotationalMotor {
          name "left_wheel"
          maxVelocity 6.702
          maxTorque 0.4
        }
      ]
      endPoint Solid {
        translation 0.04 -0.0172 0.11
        rotation 1 -1.6718433381496986e-09 -1.6718378206783447e-09 1.5707999999999913
        children [
          DEF WHEEL Shape {
            appearance PBRAppearance {
              baseColor 1 0 0
            }
            geometry Cylinder {
              height 0.02
              radius 0.0508
            }
          }
        ]
        name "left_wheel"
        boundingObject USE WHEEL
        physics Physics {
        }
      }
    }
    DEF RIGHT_WHEEL HingeJoint {
      jointParameters HingeJointParameters {
        position 4.07847065672431e-12
        axis 0 0 -1
        anchor 0.04 -0.0172 -0.11
      }
      device [
        RotationalMotor {
          name "right_wheel"
          maxVelocity 6.702
          maxTorque 0.4
        }
      ]
      endPoint Solid {
        translation 0.04 -0.0172 -0.11
        rotation -0.9999999999999999 1.87686216320634e-09 -1.8768629304986225e-09 1.5707953071795377
        children [
          USE WHEEL
        ]
        name "right_wheel"
        boundingObject USE WHEEL
        physics Physics {
        }
      }
    }
    DEF BEARING Solid {
      translation -0.06 -0.059 0
      children [
        Shape {
          appearance PBRAppearance {
            baseColor 0.5 0.5 0.5
          }
          geometry DEF Ball_bearing Sphere {
            radius 0.009
          }
        }
      ]
      name "solid(1)"
      contactMaterial "ball_bearing"
      boundingObject USE Ball_bearing
      physics Physics {
      }
    }
    DEF RIGHT_CLAW HingeJoint {
      jointParameters HingeJointParameters {
        axis 0 1 0
        anchor 0.09 0 0.03
      }
      device [
        RotationalMotor {
          name "right_claw"
        }
        PositionSensor {
          name "right_claw_sensor"
        }
      ]
      endPoint SINGLE_CLAW {
        translation 0.11499999999999999 -0.03499999999999995 0.029999999999999992
      }
    }
    DEF LEFT_CLAW HingeJoint {
      jointParameters HingeJointParameters {
        axis 0 1 0
        anchor 0.09 0 -0.03
      }
      device [
        RotationalMotor {
          name "left_claw"
        }
        PositionSensor {
          name "left_claw_sensor"
        }
      ]
      endPoint SINGLE_CLAW {
        translation 0.11499999999999999 -0.034999999999999976 -0.03000000000000001
      }
    }
    DEF BOX_CLAW HingeJoint {
      jointParameters HingeJointParameters {
        axis 0 0 1
        anchor 0.09 -0.03 0
      }
      device [
        RotationalMotor {
          name "box_claw"
        }
        PositionSensor {
          name "box_claw_sensor"
        }
      ]
    }
    DistanceSensor {
      translation 0.09 -0.055 0.01
      rotation 1 0 0 -1.5707953071795862
      children [
        Group {
          children [
            DEF ultrasonicShape Transform {
              translation 0 0.01 0
              children [
                Shape {
                  appearance PBRAppearance {
                  }
                  geometry Box {
                    size 0.015 0.045 0.02
                  }
                }
              ]
            }
          ]
        }
      ]
      name "ultrasonic"
      boundingObject USE ultrasonicShape
      lookupTable [
        0 0 0
        0.02 0 0.002
        0.02 0.02 0.002
        1.5 1.5 0.002
      ]
      type "sonar"
      aperture 0.5236
      resolution 0.003
    }
    IRSensor {
      translation 0.11 -0.03 0
    }
    TEPT4400 {
      translation 0.155 0.03 0.005
      rotation 0 0 -1 1.0472
      name "TEPT4400_RED"
      red_filter TRUE
    }
    TEPT4400 {
      translation 0.155 0.03 -0.005
      rotation 0 0 -1 1.0472
      name "TEPT4400_GREEN"
      green_filter TRUE
    }
  ]
  name "robot_red"
  physics Physics {
  }
  controller "Robot_controller"
}
target {
  translation -0.5242    0.0500   -0.1440
  name "target(9)"
}
target {
  translation -1.0665    0.0500   -0.2783
  name "target(8)"
}
target {
  translation -0.9467    0.0500    0.6240
  name "target(7)"
}
target {
  translation 0.7601    0.0500    0.6937
  name "target(6)"
}
target {
  translation 0.4578    0.0500   -0.7358
  colour 0 1 0
  name "target(5)"
}
target {
  translation -0.4298    0.0500   -0.0241
  colour 0 1 0
  name "target(1)"
}
target {
  translation 1.0580    0.0500   -0.1279
  colour 0 1 0
  name "target(2)"
}
target {
  translation -1.0941    0.0500    0.3438
  colour 0 1 0
  name "target(3)"
}
DEF Floor_colour Solid {
  translation 0 0.0001 0.4
  children [
    Shape {
      appearance PBRAppearance {
        baseColor 1 0 0
      }
      geometry Plane {
        size 0.4 0.4
      }
    }
  ]
  name "solid(6)"
}
DEF Floor_colour Solid {
  translation 0 0.0001 -0.4
  children [
    Shape {
      appearance PBRAppearance {
        baseColor 0 1 0
      }
      geometry Plane {
        size 0.4 0.4
      }
    }
  ]
  name "solid(5)"
}
DEF WALL_1 Solid {
  translation 1.2 0.05 0
  children [
    DEF WALL_SHAPE Shape {
      appearance PBRAppearance {
        baseColor 0 0.333333 0
        roughness 1
        metalness 0
      }
      geometry Box {
        size 0.02 0.1 2.38
      }
    }
  ]
  boundingObject USE WALL_SHAPE
}
DEF WALL_2 Solid {
  translation -1.2 0.05 0
  children [
    USE WALL_SHAPE
  ]
  name "solid(1)"
  boundingObject USE WALL_SHAPE
}
DEF WALL_3 Solid {
  translation 0 0.05 -1.2
  rotation 0 1 0 1.5708
  children [
    USE WALL_SHAPE
  ]
  name "solid(2)"
  boundingObject USE WALL_SHAPE
}
DEF WALL_4 Solid {
  translation 0 0.05 1.2
  rotation 0 1 0 1.5708
  children [
    USE WALL_SHAPE
  ]
  name "solid(3)"
  boundingObject USE WALL_SHAPE
}
TexturedBackgroundLight {
  texture "empty_office"
}
