#VRML_SIM R2021a utf8
WorldInfo {
  basicTimeStep 16
  coordinateSystem "NUE"
  contactProperties [
    ContactProperties {
      material2 "slippy"
      coulombFriction [
        0
      ]
    }
    ContactProperties {
      material2 "block"
      coulombFriction [
        0.01
      ]
    }
    ContactProperties {
      material2 "ball_bearing"
      coulombFriction [
        0
      ]
    }
  ]
}
Viewpoint {
  orientation 0.5376125756122595 -0.6274395097817133 -0.5632871204886863 4.337760591260682
  position 1.2024862736231856 1.1297415626580734 -0.1757777946067697
}
Background {
  skyColor [
    0.15 0.45 1
  ]
}
Floor {
  size 2.4 2.4
  appearance Asphalt {
  }
}
Robot {
  translation 0.920291 0.06 -0.248057
  rotation 0.0012617578396568994 1.3537918758716176e-06 0.9999992039823438 0.0013624617687495327
  children [
    Compass {
    }
    GPS {
    }
    Receiver {
      channel 1
    }
    Emitter {
    }
    DEF BODY Shape {
      appearance PBRAppearance {
        baseColor 0 0 1
      }
      geometry Box {
        size 0.2 0.1 0.2
      }
    }
    DEF LEFT_WHEEL HingeJoint {
      jointParameters HingeJointParameters {
        position 4.074892064168798e-12
        axis 0 0 -1
        anchor 0.04 -0.01 0.11
      }
      device [
        RotationalMotor {
          name "left_wheel"
        }
      ]
      endPoint Solid {
        translation 0.04 -0.01 0.11
        rotation -1 1.6795372595228404e-09 -1.6795316851372368e-09 1.5708000008261545
        scale 2 2 2
        children [
          DEF WHEEL Shape {
            appearance PBRAppearance {
              baseColor 1 0 0
            }
            geometry Cylinder {
              height 0.01
              radius 0.025
            }
          }
        ]
        name "left_wheel"
        boundingObject USE WHEEL
        physics Physics {
        }
      }
    }
    DEF RIGHT_WHEEL HingeJoint {
      jointParameters HingeJointParameters {
        position 4.07847065672431e-12
        axis 0 0 -1
        anchor 0.04 -0.01 -0.11
      }
      device [
        RotationalMotor {
          name "right_wheel"
        }
      ]
      endPoint Solid {
        translation 0.04 -0.01 -0.11
        rotation -1 1.3870920224795674e-10 -1.3463065841943952e-10 1.570799998166978
        scale 2 2 2
        children [
          USE WHEEL
        ]
        name "right_wheel"
        boundingObject USE WHEEL
        physics Physics {
        }
      }
    }
    DEF BEARING Solid {
      translation -0.04 -0.035 0
      children [
        Shape {
          appearance PBRAppearance {
            baseColor 0.5 0.5 0.5
          }
          geometry DEF Ball_bearing Sphere {
            radius 0.025
          }
        }
      ]
      name "solid(1)"
      contactMaterial "ball_bearing"
      boundingObject USE Ball_bearing
      physics Physics {
      }
    }
    DEF RIGHT_CLAW HingeJoint {
      jointParameters HingeJointParameters {
        position -1.7767973758964217e-09
        anchor 0.045 0 0.02
      }
      device [
        RotationalMotor {
          name "right_claw"
        }
      ]
    }
    DEF LEFT_CLAW HingeJoint {
      jointParameters HingeJointParameters {
        position -1.7767982640748414e-09
        anchor 0.045 0 -0.02
      }
      device [
        RotationalMotor {
          name "left_claw"
        }
      ]
    }
    DEF BOX_CLAW HingeJoint {
      jointParameters HingeJointParameters {
        axis 0 0 1
        anchor 0.09 -0.03 0
      }
      device [
        RotationalMotor {
          name "box_claw"
        }
        PositionSensor {
          name "box_claw_sensor"
        }
      ]
      endPoint Solid {
        translation 6.735556468129289e-08 2.0206451331605813e-07 -5.551115123125783e-17
        rotation 1.605282590659393e-14 -5.044470241384965e-15 -1 2.2446906936518976e-06
        children [
          DEF BOX_CLAW Group {
            children [
              Transform {
                translation 0.15 -0.03 -0.04
                children [
                  Shape {
                    appearance PBRAppearance {
                      baseColor 0.1 0.1 0.1
                    }
                    geometry Box {
                      size 0.15 0.01 0.01
                    }
                  }
                ]
              }
              Transform {
                translation 0.15 -0.03 0.04
                children [
                  Shape {
                    appearance PBRAppearance {
                      baseColor 0.1 0.1 0.1
                    }
                    geometry Box {
                      size 0.15 0.01 0.01
                    }
                  }
                ]
              }
              Transform {
                translation 0.23 -0.03 0
                children [
                  Shape {
                    appearance PBRAppearance {
                      baseColor 0.1 0.1 0.1
                    }
                    geometry Box {
                      size 0.01 0.01 0.09
                    }
                  }
                ]
              }
            ]
          }
        ]
        boundingObject USE BOX_CLAW
        physics Physics {
          density 0.001
        }
      }
    }
    DistanceSensor {
      translation 0.06 -0.005 0.01
      rotation 1 0 0 -1.5707953071795862
      children [
        Group {
          children [
            DEF ultrasonicShape Transform {
              translation 0 0.01 0
              children [
                Shape {
                  appearance PBRAppearance {
                  }
                  geometry Box {
                    size 0.015 0.045 0.02
                  }
                }
              ]
            }
          ]
        }
      ]
      name "ultrasonic"
      boundingObject USE ultrasonicShape
      lookupTable [
        0 0 0
        0.02 0 0
        0.02 0.02 0
        1.5 1.5 0
      ]
      type "sonar"
      aperture 0.5236
      resolution 0.003
    }
    SharpGP2Y0A02YK0F {
      translation 0.11 -0.03 0
      name "IR Sensor"
    }
    TEPT4400 {
      translation 0 0.03 0
    }
  ]
  physics Physics {
  }
  controller "Robot_controller"
}
target {
  translation -0.639 0.02497547451951153 0.42
  rotation -0.0757765602233323 0.6481120312050156 -0.7577656022333216 -5.626088597840589e-17
  name "target(9)"
}
target {
  translation 0.977 0.024975474519511525 0.6057
  rotation -0.03896321197617513 0.9898912831673099 -0.13637124191660205 2.1883495730114342e-16
  name "target(8)"
}
target {
  translation 0.6867 0.024975474519511525 0.5714
  rotation -0.03896321197617513 0.9898912831673099 -0.13637124191660205 2.1883495730114342e-16
  name "target(7)"
}
target {
  translation 1.0798 0.02497547451951153 -0.2533
  rotation 0.8059109309098598 0.24868508169517867 -0.537273953939948 6.347981521601662e-17
  name "target(6)"
}
target {
  translation 0.0670387 0.0249755 -0.00781176
  rotation 0.5132896048118902 0.06843372636024753 -0.8554826746863458 2.491725747762101e-17
  colour 0 1 0
  name "target(5)"
}
target {
  translation -1.0911 0.02497547451951153 -0.7727
  rotation -0.543436796603501 0.8394500867218522 4.124367488403013e-15 -2.3534970991322053e-17
  colour 0 1 0
  name "target(1)"
}
target {
  translation 0.8205 0.024975474519511525 0.4842
  rotation 0.5276696975222741 0.3083589524073046 0.7915045462832297 1.6158807051378174e-17
  colour 0 1 0
  name "target(2)"
}
target {
  translation 1.0199 0.02497547451951153 -1.1002
  rotation -0.47936571947404333 0.8442515227948549 0.23968285973698936 3.55741450952181e-17
  colour 0 1 0
  name "target(3)"
}
DEF Floor_colour Solid {
  translation 0 0.0001 0.4
  children [
    Shape {
      appearance PBRAppearance {
        baseColor 1 0 0
      }
      geometry Plane {
        size 0.4 0.4
      }
    }
  ]
  name "solid(6)"
}
DEF Floor_colour Solid {
  translation 0 0.0001 -0.4
  children [
    Shape {
      appearance PBRAppearance {
        baseColor 0 1 0
      }
      geometry Plane {
        size 0.4 0.4
      }
    }
  ]
  name "solid(5)"
}
DEF WALL_1 Solid {
  translation 1.2 0.05 0
  children [
    DEF WALL_SHAPE Shape {
      appearance PBRAppearance {
        baseColor 0 0.333333 0
        roughness 1
        metalness 0
      }
      geometry Box {
        size 0.02 0.1 2.38
      }
    }
  ]
  boundingObject USE WALL_SHAPE
}
DEF WALL_2 Solid {
  translation -1.2 0.05 0
  children [
    USE WALL_SHAPE
  ]
  name "solid(1)"
  boundingObject USE WALL_SHAPE
}
DEF WALL_3 Solid {
  translation 0 0.05 -1.2
  rotation 0 1 0 1.5708
  children [
    USE WALL_SHAPE
  ]
  name "solid(2)"
  boundingObject USE WALL_SHAPE
}
DEF WALL_4 Solid {
  translation 0 0.05 1.2
  rotation 0 1 0 1.5708
  children [
    USE WALL_SHAPE
  ]
  name "solid(3)"
  boundingObject USE WALL_SHAPE
}
TexturedBackgroundLight {
  texture "empty_office"
}
