#VRML_SIM R2021a utf8
WorldInfo {
  basicTimeStep 16
  coordinateSystem "NUE"
  contactProperties [
    ContactProperties {
      material2 "slippy"
      coulombFriction [
        0
      ]
    }
    ContactProperties {
      material2 "block"
      coulombFriction [
        0.01
      ]
    }
    ContactProperties {
      material2 "ball_bearing"
      coulombFriction [
        0
      ]
    }
  ]
}
Viewpoint {
  orientation -0.41957929318168546 -0.8244192380388328 -0.3798501503022314 1.8208406560289503
  position 0.5389263464797691 0.6248315501665145 0.1888221669955893
}
Background {
  skyColor [
    0.15 0.45 1
  ]
}
Floor {
  size 2.4 2.4
  appearance Asphalt {
  }
}
Robot {
  translation 0.935424 0.07 0.0657684
  rotation 0 1 0 -1.5707953071795862
  children [
    Compass {
      name "compass1"
    }
    Compass {
      rotation 0 1 0 -1.5708
    }
    GPS {
    }
    Receiver {
      channel 1
    }
    Emitter {
    }
    DEF BODY Solid {
      rotation 0 1 0 4.692820414042842e-06
      children [
        Shape {
          appearance PBRAppearance {
            baseColor 0 0 1
          }
          geometry DEF SOLIDBOX Box {
            size 0.2 0.1 0.2
          }
        }
      ]
      name "solid(2)"
      boundingObject USE SOLIDBOX
      physics Physics {
      }
    }
    DEF LEFT_WHEEL HingeJoint {
      jointParameters HingeJointParameters {
        position 4.074892064168798e-12
        axis 0 0 -1
        anchor 0.04 -0.02 0.11
      }
      device [
        RotationalMotor {
          name "left_wheel"
        }
      ]
      endPoint Solid {
        translation 0.04 -0.02 0.11
        rotation 1 -6.112338096893731e-12 -6.112315645006495e-12 1.5707999999999982
        children [
          DEF WHEEL Shape {
            appearance PBRAppearance {
              baseColor 1 0 0
            }
            geometry Cylinder {
              height 0.01
              radius 0.05
            }
          }
        ]
        name "left_wheel"
        boundingObject USE WHEEL
        physics Physics {
        }
      }
    }
    DEF RIGHT_WHEEL HingeJoint {
      jointParameters HingeJointParameters {
        position 4.07847065672431e-12
        axis 0 0 -1
        anchor 0.04 -0.02 -0.11
      }
      device [
        RotationalMotor {
          name "right_wheel"
        }
      ]
      endPoint Solid {
        translation 0.04 -0.02 -0.11
        rotation -0.9999999999999999 6.117705986200253e-12 -6.117712223193079e-12 1.570795307179576
        children [
          USE WHEEL
        ]
        name "right_wheel"
        boundingObject USE WHEEL
        physics Physics {
        }
      }
    }
    DEF BEARING Solid {
      translation -0.06 -0.035 0
      children [
        Shape {
          appearance PBRAppearance {
            baseColor 0.5 0.5 0.5
          }
          geometry DEF Ball_bearing Sphere {
            radius 0.035
          }
        }
      ]
      name "solid(1)"
      contactMaterial "ball_bearing"
      boundingObject USE Ball_bearing
      physics Physics {
      }
    }
    DEF RIGHT_CLAW HingeJoint {
      jointParameters HingeJointParameters {
        position -1.7767973758964217e-09
        anchor 0.045 0 0.02
      }
      device [
        RotationalMotor {
          name "right_claw"
        }
        PositionSensor {
          name "right_claw_sensor"
        }
      ]
    }
    DEF LEFT_CLAW HingeJoint {
      jointParameters HingeJointParameters {
        position -1.7767982640748414e-09
        anchor 0.045 0 -0.02
      }
      device [
        RotationalMotor {
          name "left_claw"
        }
        PositionSensor {
          name "left_claw_sensor"
        }
      ]
    }
    DEF BOX_CLAW HingeJoint {
      jointParameters HingeJointParameters {
        axis 0 0 1
        anchor 0.09 -0.03 0
      }
      device [
        RotationalMotor {
          name "box_claw"
        }
        PositionSensor {
          name "box_claw_sensor"
        }
      ]
      endPoint BOX_CLAW {
      }
    }
    DistanceSensor {
      translation 0.06 -0.005 0.01
      rotation 1 0 0 -1.5707953071795862
      children [
        Group {
          children [
            DEF ultrasonicShape Transform {
              translation 0 0.01 0
              children [
                Shape {
                  appearance PBRAppearance {
                  }
                  geometry Box {
                    size 0.015 0.045 0.02
                  }
                }
              ]
            }
          ]
        }
      ]
      name "ultrasonic"
      boundingObject USE ultrasonicShape
      lookupTable [
        0 0 0
        0.02 0 0.002
        0.02 0.02 0.002
        1.5 1.5 0.002
      ]
      type "sonar"
      aperture 0.5236
      resolution 0.003
    }
    SharpGP2Y0A02YK0F {
      translation 0.11 -0.03 0
      name "IR Sensor"
    }
    TEPT4400_RED {
      translation 0.16 0.04 -0.005
      rotation 0 0 1 -1.5707953071795862
    }
    TEPT4400_GREEN {
      translation 0.16 0.04 0
      rotation 0 0 1 -1.5707953071795862
    }
  ]
  physics Physics {
  }
  controller "Robot_controller"
}
target {
  translation -0.639 0.02497547451951153 0.42
  rotation -0.0757765602233323 0.6481120312050156 -0.7577656022333216 -5.626088597840589e-17
  name "target(9)"
}
target {
  translation 0.977 0.024975474519511525 0.6057
  rotation -0.03896321197617513 0.9898912831673099 -0.13637124191660205 2.1883495730114342e-16
  name "target(8)"
}
target {
  translation 0.6867 0.024975474519511525 0.5714
  rotation -0.03896321197617513 0.9898912831673099 -0.13637124191660205 2.1883495730114342e-16
  name "target(7)"
}
target {
  translation 1.0798 0.02497547451951153 -0.2533
  rotation 0.8059109309098598 0.24868508169517867 -0.537273953939948 6.347981521601662e-17
  name "target(6)"
}
target {
  translation 0.347039 0.0249755 0.812188
  rotation 0.5132896048118902 0.06843372636024753 -0.8554826746863458 2.491725747762101e-17
  colour 0 1 0
  name "target(5)"
}
target {
  translation -1.0911 0.02497547451951153 -0.7727
  rotation -0.543436796603501 0.8394500867218522 4.124367488403013e-15 -2.3534970991322053e-17
  colour 0 1 0
  name "target(1)"
}
target {
  translation 0.8205 0.024975474519511525 0.4842
  rotation 0.5276696975222741 0.3083589524073046 0.7915045462832297 1.6158807051378174e-17
  colour 0 1 0
  name "target(2)"
}
target {
  translation 1.0199 0.02497547451951153 -1.1002
  rotation -0.47936571947404333 0.8442515227948549 0.23968285973698936 3.55741450952181e-17
  colour 0 1 0
  name "target(3)"
}
DEF Floor_colour Solid {
  translation 0 0.0001 0.4
  children [
    Shape {
      appearance PBRAppearance {
        baseColor 1 0 0
      }
      geometry Plane {
        size 0.4 0.4
      }
    }
  ]
  name "solid(6)"
}
DEF Floor_colour Solid {
  translation 0 0.0001 -0.4
  children [
    Shape {
      appearance PBRAppearance {
        baseColor 0 1 0
      }
      geometry Plane {
        size 0.4 0.4
      }
    }
  ]
  name "solid(5)"
}
DEF WALL_1 Solid {
  translation 1.2 0.05 0
  children [
    DEF WALL_SHAPE Shape {
      appearance PBRAppearance {
        baseColor 0 0.333333 0
        roughness 1
        metalness 0
      }
      geometry Box {
        size 0.02 0.1 2.38
      }
    }
  ]
  boundingObject USE WALL_SHAPE
}
DEF WALL_2 Solid {
  translation -1.2 0.05 0
  children [
    USE WALL_SHAPE
  ]
  name "solid(1)"
  boundingObject USE WALL_SHAPE
}
DEF WALL_3 Solid {
  translation 0 0.05 -1.2
  rotation 0 1 0 1.5708
  children [
    USE WALL_SHAPE
  ]
  name "solid(2)"
  boundingObject USE WALL_SHAPE
}
DEF WALL_4 Solid {
  translation 0 0.05 1.2
  rotation 0 1 0 1.5708
  children [
    USE WALL_SHAPE
  ]
  name "solid(3)"
  boundingObject USE WALL_SHAPE
}
TexturedBackgroundLight {
  texture "empty_office"
}
