#VRML_SIM R2021a utf8
WorldInfo {
  basicTimeStep 16
  coordinateSystem "NUE"
  contactProperties [
    ContactProperties {
      material2 "slippy"
      coulombFriction [
        0
      ]
    }
    ContactProperties {
      material2 "block"
      coulombFriction [
        0.01
      ]
    }
    ContactProperties {
      material2 "ball_bearing"
      coulombFriction [
        0
      ]
    }
  ]
}
Viewpoint {
  orientation -0.20713749336974976 -0.8582125377862911 -0.4696437999451397 2.5501100384480364
  position -0.9490527437589176 2.6461849554018197 -1.4364582076954775
}
Background {
  skyColor [
    0.15 0.45 1
  ]
}
Floor {
  size 2.4 2.4
  appearance Asphalt {
  }
}
Robot {
  translation 0 0.068 -0.4
  children [
    Compass {
      name "compass1"
    }
    Compass {
      rotation 0 1 0 -1.5708
    }
    GPS {
    }
    Receiver {
      channel 1
    }
    Emitter {
      channel 1
    }
    DEF BODY Solid {
      rotation 0 1 0 4.692820414042842e-06
      children [
        Shape {
          appearance PBRAppearance {
            baseColor 0 0 1
          }
          geometry DEF SOLIDBOX Box {
            size 0.2 0.1 0.2
          }
        }
      ]
      name "solid(2)"
      boundingObject USE SOLIDBOX
      physics Physics {
      }
    }
    DEF LEFT_WHEEL HingeJoint {
      jointParameters HingeJointParameters {
        position 4.074892064168798e-12
        axis 0 0 -1
        anchor 0.04 -0.0172 0.11
      }
      device [
        RotationalMotor {
          name "left_wheel"
          maxVelocity 6.702
          maxTorque 0.4
        }
      ]
      endPoint Solid {
        translation 0.04 -0.0172 0.11
        rotation 1 -6.479078382236169e-10 -6.47905458324403e-10 1.5707999999999938
        children [
          DEF WHEEL Shape {
            appearance PBRAppearance {
              baseColor 1 0 0
            }
            geometry Cylinder {
              height 0.02
              radius 0.0508
            }
          }
        ]
        name "left_wheel"
        boundingObject USE WHEEL
        physics Physics {
        }
      }
    }
    DEF RIGHT_WHEEL HingeJoint {
      jointParameters HingeJointParameters {
        position 4.07847065672431e-12
        axis 0 0 -1
        anchor 0.04 -0.0172 -0.11
      }
      device [
        RotationalMotor {
          name "right_wheel"
          maxVelocity 6.702
          maxTorque 0.4
        }
      ]
      endPoint Solid {
        translation 0.04 -0.0172 -0.11
        rotation -0.9999999999999999 6.484768344130897e-10 -6.484774956113556e-10 1.5707953071795442
        children [
          USE WHEEL
        ]
        name "right_wheel"
        boundingObject USE WHEEL
        physics Physics {
        }
      }
    }
    DEF BEARING Solid {
      translation -0.06 -0.059 0
      children [
        Shape {
          appearance PBRAppearance {
            baseColor 0.5 0.5 0.5
          }
          geometry DEF Ball_bearing Sphere {
            radius 0.009
          }
        }
      ]
      name "solid(1)"
      contactMaterial "ball_bearing"
      boundingObject USE Ball_bearing
      physics Physics {
      }
    }
    DEF RIGHT_CLAW HingeJoint {
      jointParameters HingeJointParameters {
        axis 0 1 0
        anchor 0.09 0 0.03
      }
      device [
        RotationalMotor {
          name "right_claw"
        }
        PositionSensor {
          name "right_claw_sensor"
        }
      ]
      endPoint SINGLE_CLAW {
        translation 0.1550000000000001 -0.035000000926675975 0.02999999675663184
      }
    }
    DEF LEFT_CLAW HingeJoint {
      jointParameters HingeJointParameters {
        axis 0 1 0
        anchor 0.09 0 -0.03
      }
      device [
        RotationalMotor {
          name "left_claw"
        }
        PositionSensor {
          name "left_claw_sensor"
        }
      ]
      endPoint SINGLE_CLAW {
        translation 0.15500000000000047 -0.03499999999999964 -0.030000000062187927
      }
    }
    DEF BOX_CLAW HingeJoint {
      jointParameters HingeJointParameters {
        axis 0 0 1
        anchor 0.09 -0.03 0
      }
      device [
        RotationalMotor {
          name "box_claw"
        }
        PositionSensor {
          name "box_claw_sensor"
        }
      ]
    }
    DistanceSensor {
      translation 0.06 -0.005 0.01
      rotation 1 0 0 -1.5707953071795862
      children [
        Group {
          children [
            DEF ultrasonicShape Transform {
              translation 0 0.01 0
              children [
                Shape {
                  appearance PBRAppearance {
                  }
                  geometry Box {
                    size 0.015 0.045 0.02
                  }
                }
              ]
            }
          ]
        }
      ]
      name "ultrasonic"
      boundingObject USE ultrasonicShape
      lookupTable [
        0 0 0
        0.02 0 0.002
        0.02 0.02 0.002
        1.5 1.5 0.002
      ]
      type "sonar"
      aperture 0.5236
      resolution 0.003
    }
    IRSensor {
      translation 0.11 -0.03 0
    }
    TEPT4400 {
      translation 0.155 0.03 0.005
      rotation 0 0 1 -1.5707953071795862
      name "TEPT4400_RED"
      red_filter TRUE
    }
    TEPT4400 {
      translation 0.155 0.03 -0.005
      rotation 0 0 1 -1.5707953071795862
      name "TEPT4400_GREEN"
      green_filter TRUE
    }
  ]
  name "robot_green"
  physics Physics {
  }
  controller "Robot_controller"
}
Robot {
  translation 0 0.068 0.4
  children [
    Compass {
      name "compass1"
    }
    Compass {
      rotation 0 1 0 -1.5708
    }
    GPS {
    }
    Receiver {
      channel 1
    }
    Emitter {
      channel 1
    }
    DEF BODY Solid {
      rotation 0 1 0 4.692820414042842e-06
      children [
        Shape {
          appearance PBRAppearance {
            baseColor 0 0 1
          }
          geometry DEF SOLIDBOX Box {
            size 0.2 0.1 0.2
          }
        }
      ]
      name "solid(2)"
      boundingObject USE SOLIDBOX
      physics Physics {
      }
    }
    DEF LEFT_WHEEL HingeJoint {
      jointParameters HingeJointParameters {
        position 4.074892064168798e-12
        axis 0 0 -1
        anchor 0.04 -0.0172 0.11
      }
      device [
        RotationalMotor {
          name "left_wheel"
          maxVelocity 6.702
          maxTorque 0.4
        }
      ]
      endPoint Solid {
        translation 0.04 -0.0172 0.11
        rotation 1 -5.593979084278779e-10 -5.593958536431922e-10 1.5707999999999938
        children [
          DEF WHEEL Shape {
            appearance PBRAppearance {
              baseColor 1 0 0
            }
            geometry Cylinder {
              height 0.02
              radius 0.0508
            }
          }
        ]
        name "left_wheel"
        boundingObject USE WHEEL
        physics Physics {
        }
      }
    }
    DEF RIGHT_WHEEL HingeJoint {
      jointParameters HingeJointParameters {
        position 4.07847065672431e-12
        axis 0 0 -1
        anchor 0.04 -0.0172 -0.11
      }
      device [
        RotationalMotor {
          name "right_wheel"
          maxVelocity 6.702
          maxTorque 0.4
        }
      ]
      endPoint Solid {
        translation 0.04 -0.0172 -0.11
        rotation -0.9999999999999999 7.634396618866356e-10 -7.634404403028236e-10 1.5707953071795442
        children [
          USE WHEEL
        ]
        name "right_wheel"
        boundingObject USE WHEEL
        physics Physics {
        }
      }
    }
    DEF BEARING Solid {
      translation -0.06 -0.059 0
      children [
        Shape {
          appearance PBRAppearance {
            baseColor 0.5 0.5 0.5
          }
          geometry DEF Ball_bearing Sphere {
            radius 0.009
          }
        }
      ]
      name "solid(1)"
      contactMaterial "ball_bearing"
      boundingObject USE Ball_bearing
      physics Physics {
      }
    }
    DEF RIGHT_CLAW HingeJoint {
      jointParameters HingeJointParameters {
        axis 0 1 0
        anchor 0.09 0 0.03
      }
      device [
        RotationalMotor {
          name "right_claw"
        }
        PositionSensor {
          name "right_claw_sensor"
        }
      ]
      endPoint SINGLE_CLAW {
        translation 0.15500000000000014 -0.035000000926675975 0.02999999675663184
      }
    }
    DEF LEFT_CLAW HingeJoint {
      jointParameters HingeJointParameters {
        axis 0 1 0
        anchor 0.09 0 -0.03
      }
      device [
        RotationalMotor {
          name "left_claw"
        }
        PositionSensor {
          name "left_claw_sensor"
        }
      ]
      endPoint SINGLE_CLAW {
        translation 0.15500000000000047 -0.03499999999999964 -0.030000000062187927
      }
    }
    DEF BOX_CLAW HingeJoint {
      jointParameters HingeJointParameters {
        axis 0 0 1
        anchor 0.09 -0.03 0
      }
      device [
        RotationalMotor {
          name "box_claw"
        }
        PositionSensor {
          name "box_claw_sensor"
        }
      ]
    }
    DistanceSensor {
      translation 0.06 -0.005 0.01
      rotation 1 0 0 -1.5707953071795862
      children [
        Group {
          children [
            DEF ultrasonicShape Transform {
              translation 0 0.01 0
              children [
                Shape {
                  appearance PBRAppearance {
                  }
                  geometry Box {
                    size 0.015 0.045 0.02
                  }
                }
              ]
            }
          ]
        }
      ]
      name "ultrasonic"
      boundingObject USE ultrasonicShape
      lookupTable [
        0 0 0
        0.02 0 0.002
        0.02 0.02 0.002
        1.5 1.5 0.002
      ]
      type "sonar"
      aperture 0.5236
      resolution 0.003
    }
    IRSensor {
      translation 0.11 -0.03 0
    }
    TEPT4400 {
      translation 0.155 0.03 0.005
      rotation 0 0 1 -1.5707953071795862
      name "TEPT4400_RED"
      red_filter TRUE
    }
    TEPT4400 {
      translation 0.155 0.03 -0.005
      rotation 0 0 1 -1.5707953071795862
      name "TEPT4400_GREEN"
      green_filter TRUE
    }
  ]
  name "robot_red"
  physics Physics {
  }
  controller "Robot_controller"
}
target {
  translation -0.829 0.0249755 0.04
  rotation -0.0757765602233323 0.6481120312050156 -0.7577656022333216 -5.626088597840589e-17
  name "target(9)"
}
target {
  translation 0.796205 0.0249755 0.7207
  rotation -3.08321e-17 -1 -5.14243e-17 0.523596
  name "target(8)"
}
target {
  translation -0.708 0.025 0.73
  rotation -0.03896321197617513 0.9898912831673099 -0.13637124191660205 2.1883495730114342e-16
  name "target(7)"
}
target {
  translation 0.798964 0.0249755 -0.57264
  rotation 0.8059109309098598 0.24868508169517867 -0.537273953939948 6.347981521601662e-17
  name "target(6)"
}
target {
  translation 0.709347 0.0249755 0.279535
  rotation -1.32079e-17 1 4.61716e-17 -0.523595307179586
  colour 0 1 0
  name "target(5)"
}
target {
  translation -0.7611 0.0249755 -0.7427
  rotation -0.543436796603501 0.8394500867218522 4.124367488403013e-15 -2.3534970991322053e-17
  colour 0 1 0
  name "target(1)"
}
target {
  translation 0.09244 0.025 1.00595
  rotation 0.5276696975222741 0.3083589524073046 0.7915045462832297 1.6158807051378174e-17
  colour 0 1 0
  name "target(2)"
}
target {
  translation -0.0001 0.0249755 -0.9202
  rotation -0.47936571947404333 0.8442515227948549 0.23968285973698936 3.55741450952181e-17
  colour 0 1 0
  name "target(3)"
}
DEF Floor_colour Solid {
  translation 0 0.0001 0.4
  children [
    Shape {
      appearance PBRAppearance {
        baseColor 1 0 0
      }
      geometry Plane {
        size 0.4 0.4
      }
    }
  ]
  name "solid(6)"
}
DEF Floor_colour Solid {
  translation 0 0.0001 -0.4
  children [
    Shape {
      appearance PBRAppearance {
        baseColor 0 1 0
      }
      geometry Plane {
        size 0.4 0.4
      }
    }
  ]
  name "solid(5)"
}
DEF WALL_1 Solid {
  translation 1.2 0.05 0
  children [
    DEF WALL_SHAPE Shape {
      appearance PBRAppearance {
        baseColor 0 0.333333 0
        roughness 1
        metalness 0
      }
      geometry Box {
        size 0.02 0.1 2.38
      }
    }
  ]
  boundingObject USE WALL_SHAPE
}
DEF WALL_2 Solid {
  translation -1.2 0.05 0
  children [
    USE WALL_SHAPE
  ]
  name "solid(1)"
  boundingObject USE WALL_SHAPE
}
DEF WALL_3 Solid {
  translation 0 0.05 -1.2
  rotation 0 1 0 1.5708
  children [
    USE WALL_SHAPE
  ]
  name "solid(2)"
  boundingObject USE WALL_SHAPE
}
DEF WALL_4 Solid {
  translation 0 0.05 1.2
  rotation 0 1 0 1.5708
  children [
    USE WALL_SHAPE
  ]
  name "solid(3)"
  boundingObject USE WALL_SHAPE
}
TexturedBackgroundLight {
  texture "empty_office"
}
