#VRML_SIM R2021a utf8
WorldInfo {
  basicTimeStep 16
  coordinateSystem "NUE"
  contactProperties [
    ContactProperties {
      material2 "slippy"
      coulombFriction [
        0
      ]
    }
    ContactProperties {
      material2 "block"
      coulombFriction [
        0.01
      ]
    }
    ContactProperties {
      material2 "ball_bearing"
      coulombFriction [
        0
      ]
    }
  ]
}
Viewpoint {
  orientation 0.05559120224213778 -0.9921866024141959 -0.11169316999283364 4.860843964325082
  position 0.3908037104644178 0.10481113988478362 0.025587210240622493
}
Background {
  skyColor [
    0.15 0.45 1
  ]
}
Floor {
  size 2.4 2.4
  appearance Asphalt {
  }
}
target {
  translation -0.639 0.05 0.42
  name "target(9)"
}
target {
  translation 0.977 0.05 0.6057
  name "target(8)"
}
target {
  translation 0.6867 0.05 0.5714
  name "target(7)"
}
target {
  translation 1.0798 0.05 -0.2533
  name "target(6)"
}
target {
  translation 0.366 0.05 0.3654
  colour 0 1 0
  name "target(5)"
}
target {
  translation -1.0911 0.05 -0.7727
  colour 0 1 0
  name "target(1)"
}
target {
  translation 0.8205 0.05 0.4842
  colour 0 1 0
  name "target(2)"
}
target {
  translation 1.0199 0.05 -1.1002
  colour 0 1 0
  name "target(3)"
}
DEF Floor_colour Solid {
  translation 0 0.0001 0.4
  children [
    Shape {
      appearance PBRAppearance {
        baseColor 1 0 0
      }
      geometry Plane {
        size 0.4 0.4
      }
    }
  ]
  name "solid(6)"
}
DEF Floor_colour Solid {
  translation 0 0.0001 -0.4
  children [
    Shape {
      appearance PBRAppearance {
        baseColor 0 1 0
      }
      geometry Plane {
        size 0.4 0.4
      }
    }
  ]
  name "solid(5)"
}
DEF WALL_1 Solid {
  translation 1.2 0.05 0
  children [
    DEF WALL_SHAPE Shape {
      appearance PBRAppearance {
        baseColor 0 0.333333 0
        roughness 1
        metalness 0
      }
      geometry Box {
        size 0.02 0.1 2.38
      }
    }
  ]
  boundingObject USE WALL_SHAPE
}
DEF WALL_2 Solid {
  translation -1.2 0.05 0
  children [
    USE WALL_SHAPE
  ]
  name "solid(1)"
  boundingObject USE WALL_SHAPE
}
DEF WALL_3 Solid {
  translation 0 0.05 -1.2
  rotation 0 1 0 1.5708
  children [
    USE WALL_SHAPE
  ]
  name "solid(2)"
  boundingObject USE WALL_SHAPE
}
DEF WALL_4 Solid {
  translation 0 0.05 1.2
  rotation 0 1 0 1.5708
  children [
    USE WALL_SHAPE
  ]
  name "solid(3)"
  boundingObject USE WALL_SHAPE
}
TexturedBackgroundLight {
  texture "empty_office"
}
Robot {
  translation 0.02 0.05 0
  children [
    DEF BODY Shape {
      appearance PBRAppearance {
        baseColor 0 0 1
      }
      geometry Box {
        size 0.1 0.03 0.05
      }
    }
    DEF LEFT_WHEEL HingeJoint {
      jointParameters HingeJointParameters {
        anchor 0.02 -0.005 0.03
      }
      device [
        RotationalMotor {
          name "left_wheel"
        }
      ]
      endPoint Solid {
        translation 0.02000000391046377 -0.004997452491810772 0.029999999997836674
        rotation -1 1.5409908384908597e-09 -1.5409861239445273e-09 1.5708000008506064
        children [
          DEF WHEEL Shape {
            appearance PBRAppearance {
              baseColor 1 0 0
            }
            geometry Cylinder {
              height 0.01
              radius 0.025
            }
          }
        ]
        name "left_wheel"
        boundingObject USE WHEEL
        physics Physics {
        }
      }
    }
    DEF RIGHT_WHEEL HingeJoint {
      jointParameters HingeJointParameters {
        anchor 0.02 -0.005 -0.03
      }
      device [
        RotationalMotor {
          name "right_wheel"
        }
      ]
      endPoint Solid {
        translation 0.020000003925813817 -0.004997598386196223 -0.030000000006616474
        rotation -1 4.113513930910408e-14 -4.209181408158462e-14 1.5707999981832914
        children [
          USE WHEEL
        ]
        name "right_wheel"
        boundingObject USE WHEEL
        physics Physics {
        }
      }
    }
    DEF BEARING Solid {
      translation -0.04 -0.02 0
      children [
        Shape {
          appearance PBRAppearance {
            baseColor 0.5 0.5 0.5
          }
          geometry DEF Ball_bearing Sphere {
            radius 0.01
          }
        }
      ]
      name "solid(1)"
      contactMaterial "ball_bearing"
      boundingObject USE Ball_bearing
      physics Physics {
      }
    }
    DEF RIGHT_CLAW HingeJoint {
      jointParameters HingeJointParameters {
        anchor 0.045 0 0.02
      }
      device [
        RotationalMotor {
          name "right_claw"
        }
      ]
      endPoint Solid {
        translation 0.08999999994309457 -3.9319495846734837e-08 0.020000000000096142
        rotation 1 0 0 0
        children [
          DEF CLAW Shape {
            appearance PBRAppearance {
              baseColor 0 0 0
            }
            geometry Box {
              size 0.1 0.01 0.005
            }
          }
        ]
        name "right_claw"
        boundingObject USE CLAW
        physics Physics {
        }
      }
    }
    DEF LEFT_CLAW HingeJoint {
      jointParameters HingeJointParameters {
        anchor 0.045 0 -0.02
      }
      device [
        RotationalMotor {
          name "left_claw"
        }
      ]
      endPoint Solid {
        translation 0.0899999999430946 -3.931949595775714e-08 -0.01999999999990385
        rotation 1 0 0 0
        children [
          DEF CLAW Shape {
            appearance PBRAppearance {
              baseColor 0 0 0
            }
            geometry Box {
              size 0.1 0.01 0.005
            }
          }
        ]
        name "left_claw"
        boundingObject USE CLAW
        physics Physics {
        }
      }
    }
    DistanceSensor {
      translation 0.06 0 0
      children [
        Shape {
          appearance PBRAppearance {
            baseColor 0 1 0.5
          }
          geometry Box {
            size 0.005 0.005 0.02
          }
        }
      ]
      name "hc_sr04"
    }
    SharpGP2Y0A02YK0F {
      translation 0.06 0.01 0.01
    }
  ]
  physics Physics {
  }
}
